{"uuid": "e5f96d25-1130-4023-a62f-66fc3962124a", "children": ["03fbf67f-3fd5-43ef-afc7-04bac5d64bb5", "568e37fc-0ae9-4a5f-b05f-3b260090f73b", "f9e922c2-c0e7-4bc4-bba1-46e2d242c0e2", "a7ce5c66-3dae-4e2e-b017-a1aebabb853a", "0006de1a-d082-4415-a07f-d693351ba903", "0661e08e-18f6-473f-9df3-3d27af47682b", "684ad7c1-9970-4f99-a503-4f4a456b8ba9", "e2836748-72c7-4586-b991-61907b5ed944"], "befores": [{"name": "app", "status": "broken", "statusDetails": {"message": "selenium.common.exceptions.WebDriverException: Message: An unknown server-side error occurred while processing the command. Original error: You must include a platformName capability\n\n", "trace": "  File \"C:\\Users\\w8345\\.conda\\envs\\pytestAutoApi\\Lib\\site-packages\\pluggy\\_callers.py\", line 167, in _multicall\n    teardown.throw(outcome._exception)\n  File \"C:\\Users\\w8345\\.conda\\envs\\pytestAutoApi\\Lib\\site-packages\\_pytest\\setuponly.py\", line 36, in pytest_fixture_setup\n    return (yield)\n            ^^^^^\n  File \"C:\\Users\\w8345\\.conda\\envs\\pytestAutoApi\\Lib\\site-packages\\pluggy\\_callers.py\", line 103, in _multicall\n    res = hook_impl.function(*args)\n          ^^^^^^^^^^^^^^^^^^^^^^^^^\n  File \"C:\\Users\\w8345\\.conda\\envs\\pytestAutoApi\\Lib\\site-packages\\_pytest\\fixtures.py\", line 1140, in pytest_fixture_setup\n    result = call_fixture_func(fixturefunc, request, kwargs)\n             ^^^^^^^^^^^^^^^^^^^^^^^^^^^^^^^^^^^^^^^^^^^^^^^\n  File \"C:\\Users\\w8345\\.conda\\envs\\pytestAutoApi\\Lib\\site-packages\\_pytest\\fixtures.py\", line 891, in call_fixture_func\n    fixture_result = next(generator)\n                     ^^^^^^^^^^^^^^^\n  File \"D:\\PytestAutoApi\\cases\\app_ui\\android\\conftest.py\", line 8, in app\n    driver = Android_UI_Client()\n             ^^^^^^^^^^^^^^^^^^^\n  File \"D:\\PytestAutoApi\\base\\android\\android_ui_client.py\", line 43, in __init__\n    self.driver = webdriver.Remote(\n                  ^^^^^^^^^^^^^^^^^\n  File \"C:\\Users\\w8345\\.conda\\envs\\pytestAutoApi\\Lib\\site-packages\\appium\\webdriver\\webdriver.py\", line 274, in __init__\n    super().__init__(\n  File \"C:\\Users\\w8345\\.conda\\envs\\pytestAutoApi\\Lib\\site-packages\\selenium\\webdriver\\remote\\webdriver.py\", line 266, in __init__\n    self.start_session(capabilities, browser_profile)\n  File \"C:\\Users\\w8345\\.conda\\envs\\pytestAutoApi\\Lib\\site-packages\\appium\\webdriver\\webdriver.py\", line 369, in start_session\n    response = self.execute(RemoteCommand.NEW_SESSION, parameters)\n               ^^^^^^^^^^^^^^^^^^^^^^^^^^^^^^^^^^^^^^^^^^^^^^^^^^^\n  File \"C:\\Users\\w8345\\.conda\\envs\\pytestAutoApi\\Lib\\site-packages\\selenium\\webdriver\\remote\\webdriver.py\", line 418, in execute\n    self.error_handler.check_response(response)\n  File \"C:\\Users\\w8345\\.conda\\envs\\pytestAutoApi\\Lib\\site-packages\\selenium\\webdriver\\remote\\errorhandler.py\", line 243, in check_response\n    raise exception_class(message, screen, stacktrace)\n"}, "start": 1757580969795, "stop": 1757580970071}], "start": 1757580969795, "stop": 1757580970417}