{"uuid": "84fc6f21-85bb-4bb3-a9c9-8308516019dc", "children": ["c88f6ec6-23a4-45a7-95cd-bf19fb63453b", "6927919a-fa98-4b79-8130-64124beaea85", "2ceb74bf-eda9-4fd8-a962-311e5778a5c6", "0444a15f-33ba-4b94-a3cf-3c85cc6d98f2", "2cc3f4aa-826b-4976-a6ab-f143b7092463", "78af489d-a76e-4411-8a22-743e103c3fb7", "91cf905a-5815-4fd3-b23d-fca111d9bc0f", "479a8d1b-1797-4726-a150-f61aa2e3386a"], "befores": [{"name": "app", "status": "broken", "statusDetails": {"message": "selenium.common.exceptions.WebDriverException: Message: An unknown server-side error occurred while processing the command. Original error: Unable to find an active device or emulator with OS 13. The following are available: R3CM801F1BY (12)\nStacktrace:\nUnknownError: An unknown server-side error occurred while processing the command. Original error: Unable to find an active device or emulator with OS 13. The following are available: R3CM801F1BY (12)\n    at getResponseForW3CError (C:\\Program Files\\Appium Server GUI\\resources\\app\\node_modules\\appium\\node_modules\\appium-base-driver\\lib\\protocol\\errors.js:804:9)\n    at asyncHandler (C:\\Program Files\\Appium Server GUI\\resources\\app\\node_modules\\appium\\node_modules\\appium-base-driver\\lib\\protocol\\protocol.js:380:37)\n", "trace": "  File \"C:\\Users\\w8345\\.conda\\envs\\pytestAutoApi\\Lib\\site-packages\\pluggy\\_callers.py\", line 167, in _multicall\n    teardown.throw(outcome._exception)\n  File \"C:\\Users\\w8345\\.conda\\envs\\pytestAutoApi\\Lib\\site-packages\\_pytest\\setuponly.py\", line 36, in pytest_fixture_setup\n    return (yield)\n            ^^^^^\n  File \"C:\\Users\\w8345\\.conda\\envs\\pytestAutoApi\\Lib\\site-packages\\pluggy\\_callers.py\", line 103, in _multicall\n    res = hook_impl.function(*args)\n          ^^^^^^^^^^^^^^^^^^^^^^^^^\n  File \"C:\\Users\\w8345\\.conda\\envs\\pytestAutoApi\\Lib\\site-packages\\_pytest\\fixtures.py\", line 1140, in pytest_fixture_setup\n    result = call_fixture_func(fixturefunc, request, kwargs)\n             ^^^^^^^^^^^^^^^^^^^^^^^^^^^^^^^^^^^^^^^^^^^^^^^\n  File \"C:\\Users\\w8345\\.conda\\envs\\pytestAutoApi\\Lib\\site-packages\\_pytest\\fixtures.py\", line 891, in call_fixture_func\n    fixture_result = next(generator)\n                     ^^^^^^^^^^^^^^^\n  File \"D:\\PytestAutoApi\\cases\\app_ui\\android\\conftest.py\", line 8, in app\n    driver = Android_UI_Client()\n             ^^^^^^^^^^^^^^^^^^^\n  File \"D:\\PytestAutoApi\\base\\android\\android_ui_client.py\", line 41, in __init__\n    self.driver = webdriver.Remote(\n                  ^^^^^^^^^^^^^^^^^\n  File \"C:\\Users\\w8345\\.conda\\envs\\pytestAutoApi\\Lib\\site-packages\\appium\\webdriver\\webdriver.py\", line 274, in __init__\n    super().__init__(\n  File \"C:\\Users\\w8345\\.conda\\envs\\pytestAutoApi\\Lib\\site-packages\\selenium\\webdriver\\remote\\webdriver.py\", line 266, in __init__\n    self.start_session(capabilities, browser_profile)\n  File \"C:\\Users\\w8345\\.conda\\envs\\pytestAutoApi\\Lib\\site-packages\\appium\\webdriver\\webdriver.py\", line 369, in start_session\n    response = self.execute(RemoteCommand.NEW_SESSION, parameters)\n               ^^^^^^^^^^^^^^^^^^^^^^^^^^^^^^^^^^^^^^^^^^^^^^^^^^^\n  File \"C:\\Users\\w8345\\.conda\\envs\\pytestAutoApi\\Lib\\site-packages\\selenium\\webdriver\\remote\\webdriver.py\", line 418, in execute\n    self.error_handler.check_response(response)\n  File \"C:\\Users\\w8345\\.conda\\envs\\pytestAutoApi\\Lib\\site-packages\\selenium\\webdriver\\remote\\errorhandler.py\", line 243, in check_response\n    raise exception_class(message, screen, stacktrace)\n"}, "start": 1757581098409, "stop": 1757581103750}], "start": 1757581098409, "stop": 1757581104065}