{"uuid": "4562a5f1-1a09-48f9-8960-276a1dd4b819", "children": ["3fb64186-f29a-4fb3-bf94-3139362fe8a4", "5a8057cd-87b7-4973-b8db-eaf09f7440e2", "867b724e-9934-41d1-99f7-2335b76a9d29", "569e3073-510d-4fbf-919f-dc6d2ede3fe8", "06b1f997-81a9-4779-ba38-2209ee01731f", "eeabfe68-9443-4806-8df9-3c9d671f5fd1", "9127e536-5b81-4974-91cd-9f02bc7eb9a6", "08872f07-1cca-4d64-bfb9-561fa3a71831"], "befores": [{"name": "app", "status": "broken", "statusDetails": {"message": "selenium.common.exceptions.WebDriverException: Message: An unknown server-side error occurred while processing the command. Original error: Cannot start the 'com.lzy.wobirdy' application. Visit https://github.com/appium/appium/blob/master/docs/en/writing-running-appium/android/activity-startup.md for troubleshooting. Original error: Cannot start the 'com.lzy.wobirdy' application. Visit https://github.com/appium/appium/blob/master/docs/en/writing-running-appium/android/activity-startup.md for troubleshooting. Original error: Activity name '.com.lzy.wobirdy.ui.activity.SplashActivity' used to start the app doesn't exist or cannot be launched! Make sure it exists and is a launchable activity\nStacktrace:\nUnknownError: An unknown server-side error occurred while processing the command. Original error: Cannot start the 'com.lzy.wobirdy' application. Visit https://github.com/appium/appium/blob/master/docs/en/writing-running-appium/android/activity-startup.md for troubleshooting. Original error: Cannot start the 'com.lzy.wobirdy' application. Visit https://github.com/appium/appium/blob/master/docs/en/writing-running-appium/android/activity-startup.md for troubleshooting. Original error: Activity name '.com.lzy.wobirdy.ui.activity.SplashActivity' used to start the app doesn't exist or cannot be launched! Make sure it exists and is a launchable activity\n    at getResponseForW3CError (C:\\Program Files\\Appium Server GUI\\resources\\app\\node_modules\\appium\\node_modules\\appium-base-driver\\lib\\protocol\\errors.js:804:9)\n    at asyncHandler (C:\\Program Files\\Appium Server GUI\\resources\\app\\node_modules\\appium\\node_modules\\appium-base-driver\\lib\\protocol\\protocol.js:380:37)\n", "trace": "  File \"C:\\Users\\w8345\\.conda\\envs\\pytestAutoApi\\Lib\\site-packages\\pluggy\\_callers.py\", line 167, in _multicall\n    teardown.throw(outcome._exception)\n  File \"C:\\Users\\w8345\\.conda\\envs\\pytestAutoApi\\Lib\\site-packages\\_pytest\\setuponly.py\", line 36, in pytest_fixture_setup\n    return (yield)\n            ^^^^^\n  File \"C:\\Users\\w8345\\.conda\\envs\\pytestAutoApi\\Lib\\site-packages\\pluggy\\_callers.py\", line 103, in _multicall\n    res = hook_impl.function(*args)\n          ^^^^^^^^^^^^^^^^^^^^^^^^^\n  File \"C:\\Users\\w8345\\.conda\\envs\\pytestAutoApi\\Lib\\site-packages\\_pytest\\fixtures.py\", line 1140, in pytest_fixture_setup\n    result = call_fixture_func(fixturefunc, request, kwargs)\n             ^^^^^^^^^^^^^^^^^^^^^^^^^^^^^^^^^^^^^^^^^^^^^^^\n  File \"C:\\Users\\w8345\\.conda\\envs\\pytestAutoApi\\Lib\\site-packages\\_pytest\\fixtures.py\", line 891, in call_fixture_func\n    fixture_result = next(generator)\n                     ^^^^^^^^^^^^^^^\n  File \"D:\\PytestAutoApi\\cases\\app_ui\\android\\conftest.py\", line 8, in app\n    driver = Android_UI_Client()\n             ^^^^^^^^^^^^^^^^^^^\n  File \"D:\\PytestAutoApi\\base\\android\\android_ui_client.py\", line 41, in __init__\n    self.driver = webdriver.Remote(\n                  ^^^^^^^^^^^^^^^^^\n  File \"C:\\Users\\w8345\\.conda\\envs\\pytestAutoApi\\Lib\\site-packages\\appium\\webdriver\\webdriver.py\", line 274, in __init__\n    super().__init__(\n  File \"C:\\Users\\w8345\\.conda\\envs\\pytestAutoApi\\Lib\\site-packages\\selenium\\webdriver\\remote\\webdriver.py\", line 266, in __init__\n    self.start_session(capabilities, browser_profile)\n  File \"C:\\Users\\w8345\\.conda\\envs\\pytestAutoApi\\Lib\\site-packages\\appium\\webdriver\\webdriver.py\", line 369, in start_session\n    response = self.execute(RemoteCommand.NEW_SESSION, parameters)\n               ^^^^^^^^^^^^^^^^^^^^^^^^^^^^^^^^^^^^^^^^^^^^^^^^^^^\n  File \"C:\\Users\\w8345\\.conda\\envs\\pytestAutoApi\\Lib\\site-packages\\selenium\\webdriver\\remote\\webdriver.py\", line 418, in execute\n    self.error_handler.check_response(response)\n  File \"C:\\Users\\w8345\\.conda\\envs\\pytestAutoApi\\Lib\\site-packages\\selenium\\webdriver\\remote\\errorhandler.py\", line 243, in check_response\n    raise exception_class(message, screen, stacktrace)\n"}, "start": 1757581818524, "stop": 1757581827102}], "start": 1757581818524, "stop": 1757581827414}