{"uuid": "ab569c60-aacd-4daa-815f-958077088956", "children": ["07c4866d-5ae5-4b73-bbb7-2524630d647a", "04f47960-e006-4365-8409-392a250c9c47", "ab75ba20-562e-4b07-add4-dd5c32c9ebb7", "57d12e93-85e3-4831-a91c-9ec1b0f1240a", "48c26d07-a21c-41c9-9a37-3747d58b722a", "330197eb-4449-4d9f-9860-636d8a4d5a6f", "9280d40f-e749-4159-ac94-0be7c7ffd8ce", "6b6c9e6f-dc72-48b4-b348-c36f294f4074"], "befores": [{"name": "app", "status": "broken", "statusDetails": {"message": "selenium.common.exceptions.WebDriverException: Message: An unknown server-side error occurred while processing the command. Original error: Unable to find an active device or emulator with OS 13. The following are available: R3CM801F1BY (12)\nStacktrace:\nUnknownError: An unknown server-side error occurred while processing the command. Original error: Unable to find an active device or emulator with OS 13. The following are available: R3CM801F1BY (12)\n    at getResponseForW3CError (C:\\Program Files\\Appium Server GUI\\resources\\app\\node_modules\\appium\\node_modules\\appium-base-driver\\lib\\protocol\\errors.js:804:9)\n    at asyncHandler (C:\\Program Files\\Appium Server GUI\\resources\\app\\node_modules\\appium\\node_modules\\appium-base-driver\\lib\\protocol\\protocol.js:380:37)\n", "trace": "  File \"C:\\Users\\w8345\\.conda\\envs\\pytestAutoApi\\Lib\\site-packages\\pluggy\\_callers.py\", line 167, in _multicall\n    teardown.throw(outcome._exception)\n  File \"C:\\Users\\w8345\\.conda\\envs\\pytestAutoApi\\Lib\\site-packages\\_pytest\\setuponly.py\", line 36, in pytest_fixture_setup\n    return (yield)\n            ^^^^^\n  File \"C:\\Users\\w8345\\.conda\\envs\\pytestAutoApi\\Lib\\site-packages\\pluggy\\_callers.py\", line 103, in _multicall\n    res = hook_impl.function(*args)\n          ^^^^^^^^^^^^^^^^^^^^^^^^^\n  File \"C:\\Users\\w8345\\.conda\\envs\\pytestAutoApi\\Lib\\site-packages\\_pytest\\fixtures.py\", line 1140, in pytest_fixture_setup\n    result = call_fixture_func(fixturefunc, request, kwargs)\n             ^^^^^^^^^^^^^^^^^^^^^^^^^^^^^^^^^^^^^^^^^^^^^^^\n  File \"C:\\Users\\w8345\\.conda\\envs\\pytestAutoApi\\Lib\\site-packages\\_pytest\\fixtures.py\", line 891, in call_fixture_func\n    fixture_result = next(generator)\n                     ^^^^^^^^^^^^^^^\n  File \"D:\\PytestAutoApi\\cases\\app_ui\\android\\conftest.py\", line 8, in app\n    driver = Android_UI_Client()\n             ^^^^^^^^^^^^^^^^^^^\n  File \"D:\\PytestAutoApi\\base\\android\\android_ui_client.py\", line 41, in __init__\n    self.driver = webdriver.Remote(\n                  ^^^^^^^^^^^^^^^^^\n  File \"C:\\Users\\w8345\\.conda\\envs\\pytestAutoApi\\Lib\\site-packages\\appium\\webdriver\\webdriver.py\", line 274, in __init__\n    super().__init__(\n  File \"C:\\Users\\w8345\\.conda\\envs\\pytestAutoApi\\Lib\\site-packages\\selenium\\webdriver\\remote\\webdriver.py\", line 266, in __init__\n    self.start_session(capabilities, browser_profile)\n  File \"C:\\Users\\w8345\\.conda\\envs\\pytestAutoApi\\Lib\\site-packages\\appium\\webdriver\\webdriver.py\", line 369, in start_session\n    response = self.execute(RemoteCommand.NEW_SESSION, parameters)\n               ^^^^^^^^^^^^^^^^^^^^^^^^^^^^^^^^^^^^^^^^^^^^^^^^^^^\n  File \"C:\\Users\\w8345\\.conda\\envs\\pytestAutoApi\\Lib\\site-packages\\selenium\\webdriver\\remote\\webdriver.py\", line 418, in execute\n    self.error_handler.check_response(response)\n  File \"C:\\Users\\w8345\\.conda\\envs\\pytestAutoApi\\Lib\\site-packages\\selenium\\webdriver\\remote\\errorhandler.py\", line 243, in check_response\n    raise exception_class(message, screen, stacktrace)\n"}, "start": 1757581502551, "stop": 1757581502878}], "start": 1757581502551, "stop": 1757581503204}