{"uuid": "468cb639-ae32-4ec9-b4ab-81160316c40d", "children": ["2e9ce653-957b-440a-adb3-4344c87aea4d", "40ecf14e-5f21-4d59-aefa-97797a35bb48", "377f22cc-b96d-42fb-8841-81a25e6318bf", "ac197089-e5e7-4f7e-82a8-773701c2d566", "b914e989-b1ae-406b-bb1c-3792338b5933", "17bc96eb-157d-4289-b600-abef7f5ecf1d", "737faf27-6a3a-473f-ac0e-0e66425662a4", "fda6ecff-bd7d-473e-bb72-0f30f7bdb8ea"], "befores": [{"name": "app", "status": "broken", "statusDetails": {"message": "selenium.common.exceptions.WebDriverException: Message: An unknown server-side error occurred while processing the command. Original error: Unable to find an active device or emulator with OS 13. The following are available: R3CM801F1BY (12)\nStacktrace:\nUnknownError: An unknown server-side error occurred while processing the command. Original error: Unable to find an active device or emulator with OS 13. The following are available: R3CM801F1BY (12)\n    at getResponseForW3CError (C:\\Program Files\\Appium Server GUI\\resources\\app\\node_modules\\appium\\node_modules\\appium-base-driver\\lib\\protocol\\errors.js:804:9)\n    at asyncHandler (C:\\Program Files\\Appium Server GUI\\resources\\app\\node_modules\\appium\\node_modules\\appium-base-driver\\lib\\protocol\\protocol.js:380:37)\n", "trace": "  File \"C:\\Users\\w8345\\.conda\\envs\\pytestAutoApi\\Lib\\site-packages\\pluggy\\_callers.py\", line 167, in _multicall\n    teardown.throw(outcome._exception)\n  File \"C:\\Users\\w8345\\.conda\\envs\\pytestAutoApi\\Lib\\site-packages\\_pytest\\setuponly.py\", line 36, in pytest_fixture_setup\n    return (yield)\n            ^^^^^\n  File \"C:\\Users\\w8345\\.conda\\envs\\pytestAutoApi\\Lib\\site-packages\\pluggy\\_callers.py\", line 103, in _multicall\n    res = hook_impl.function(*args)\n          ^^^^^^^^^^^^^^^^^^^^^^^^^\n  File \"C:\\Users\\w8345\\.conda\\envs\\pytestAutoApi\\Lib\\site-packages\\_pytest\\fixtures.py\", line 1140, in pytest_fixture_setup\n    result = call_fixture_func(fixturefunc, request, kwargs)\n             ^^^^^^^^^^^^^^^^^^^^^^^^^^^^^^^^^^^^^^^^^^^^^^^\n  File \"C:\\Users\\w8345\\.conda\\envs\\pytestAutoApi\\Lib\\site-packages\\_pytest\\fixtures.py\", line 891, in call_fixture_func\n    fixture_result = next(generator)\n                     ^^^^^^^^^^^^^^^\n  File \"D:\\PytestAutoApi\\cases\\app_ui\\android\\conftest.py\", line 8, in app\n    driver = Android_UI_Client()\n             ^^^^^^^^^^^^^^^^^^^\n  File \"D:\\PytestAutoApi\\base\\android\\android_ui_client.py\", line 41, in __init__\n    self.driver = webdriver.Remote(\n                  ^^^^^^^^^^^^^^^^^\n  File \"C:\\Users\\w8345\\.conda\\envs\\pytestAutoApi\\Lib\\site-packages\\appium\\webdriver\\webdriver.py\", line 274, in __init__\n    super().__init__(\n  File \"C:\\Users\\w8345\\.conda\\envs\\pytestAutoApi\\Lib\\site-packages\\selenium\\webdriver\\remote\\webdriver.py\", line 266, in __init__\n    self.start_session(capabilities, browser_profile)\n  File \"C:\\Users\\w8345\\.conda\\envs\\pytestAutoApi\\Lib\\site-packages\\appium\\webdriver\\webdriver.py\", line 369, in start_session\n    response = self.execute(RemoteCommand.NEW_SESSION, parameters)\n               ^^^^^^^^^^^^^^^^^^^^^^^^^^^^^^^^^^^^^^^^^^^^^^^^^^^\n  File \"C:\\Users\\w8345\\.conda\\envs\\pytestAutoApi\\Lib\\site-packages\\selenium\\webdriver\\remote\\webdriver.py\", line 418, in execute\n    self.error_handler.check_response(response)\n  File \"C:\\Users\\w8345\\.conda\\envs\\pytestAutoApi\\Lib\\site-packages\\selenium\\webdriver\\remote\\errorhandler.py\", line 243, in check_response\n    raise exception_class(message, screen, stacktrace)\n"}, "start": 1757581446411, "stop": 1757581446721}], "start": 1757581446411, "stop": 1757581447034}